Workbook

Sheet Tổng hợp
A1: Tổng hợp tiến độ test
A3: Nhóm | B3: Tổng | C3: Positive | D3: Negative | E3: Edge | F3: P1 | G3: Pass | H3: Fail | I3: Blocked | J3: N/A | K3: Chưa test | L3: % đã chạy
A4: 1. Liên kết QR (Gopany) | B4: =COUNTIF(Testcase!$B$5:$B$104,$A4) -> 16 | C4: =COUNTIFS(Testcase!$B$5:$B$104,$A4,Testcase!$C$5:$C$104,"Positive") -> 4 | D4: =COUNTIFS(Testcase!$B$5:$B$104,$A4,Testcase!$C$5:$C$104,"Negative") -> 3 | E4: =COUNTIFS(Testcase!$B$5:$B$104,$A4,Testcase!$C$5:$C$104,"Edge") -> 9 | F4: =COUNTIFS(Testcase!$B$5:$B$104,$A4,Testcase!$D$5:$D$104,"P1") -> 9 | G4: =COUNTIFS(Testcase!$B$5:$B$104,$A4,Testcase!$I$5:$I$104,"Pass") -> 0 | H4: =COUNTIFS(Testcase!$B$5:$B$104,$A4,Testcase!$I$5:$I$104,"Fail") -> 0 | I4: =COUNTIFS(Testcase!$B$5:$B$104,$A4,Testcase!$I$5:$I$104,"Blocked") -> 0 | J4: =COUNTIFS(Testcase!$B$5:$B$104,$A4,Testcase!$I$5:$I$104,"N/A") -> 0 | K4: =COUNTIFS(Testcase!$B$5:$B$104,$A4,Testcase!$I$5:$I$104,"Chưa test") -> 16 | L4: =IF(B4=0,0,(B4-K4)/B4) -> 0
A5: 2. Danh sách admin zaloHub | B5: =COUNTIF(Testcase!$B$5:$B$104,$A5) -> 15 | C5: =COUNTIFS(Testcase!$B$5:$B$104,$A5,Testcase!$C$5:$C$104,"Positive") -> 9 | D5: =COUNTIFS(Testcase!$B$5:$B$104,$A5,Testcase!$C$5:$C$104,"Negative") -> 0 | E5: =COUNTIFS(Testcase!$B$5:$B$104,$A5,Testcase!$C$5:$C$104,"Edge") -> 6 | F5: =COUNTIFS(Testcase!$B$5:$B$104,$A5,Testcase!$D$5:$D$104,"P1") -> 2 | G5: =COUNTIFS(Testcase!$B$5:$B$104,$A5,Testcase!$I$5:$I$104,"Pass") -> 0 | H5: =COUNTIFS(Testcase!$B$5:$B$104,$A5,Testcase!$I$5:$I$104,"Fail") -> 0 | I5: =COUNTIFS(Testcase!$B$5:$B$104,$A5,Testcase!$I$5:$I$104,"Blocked") -> 0 | J5: =COUNTIFS(Testcase!$B$5:$B$104,$A5,Testcase!$I$5:$I$104,"N/A") -> 0 | K5: =COUNTIFS(Testcase!$B$5:$B$104,$A5,Testcase!$I$5:$I$104,"Chưa test") -> 15 | L5: =IF(B5=0,0,(B5-K5)/B5) -> 0
A6: 3. Đồng bộ | B6: =COUNTIF(Testcase!$B$5:$B$104,$A6) -> 29 | C6: =COUNTIFS(Testcase!$B$5:$B$104,$A6,Testcase!$C$5:$C$104,"Positive") -> 6 | D6: =COUNTIFS(Testcase!$B$5:$B$104,$A6,Testcase!$C$5:$C$104,"Negative") -> 7 | E6: =COUNTIFS(Testcase!$B$5:$B$104,$A6,Testcase!$C$5:$C$104,"Edge") -> 16 | F6: =COUNTIFS(Testcase!$B$5:$B$104,$A6,Testcase!$D$5:$D$104,"P1") -> 19 | G6: =COUNTIFS(Testcase!$B$5:$B$104,$A6,Testcase!$I$5:$I$104,"Pass") -> 0 | H6: =COUNTIFS(Testcase!$B$5:$B$104,$A6,Testcase!$I$5:$I$104,"Fail") -> 0 | I6: =COUNTIFS(Testcase!$B$5:$B$104,$A6,Testcase!$I$5:$I$104,"Blocked") -> 0 | J6: =COUNTIFS(Testcase!$B$5:$B$104,$A6,Testcase!$I$5:$I$104,"N/A") -> 0 | K6: =COUNTIFS(Testcase!$B$5:$B$104,$A6,Testcase!$I$5:$I$104,"Chưa test") -> 29 | L6: =IF(B6=0,0,(B6-K6)/B6) -> 0
A7: 4. Hủy đồng bộ | B7: =COUNTIF(Testcase!$B$5:$B$104,$A7) -> 8 | C7: =COUNTIFS(Testcase!$B$5:$B$104,$A7,Testcase!$C$5:$C$104,"Positive") -> 2 | D7: =COUNTIFS(Testcase!$B$5:$B$104,$A7,Testcase!$C$5:$C$104,"Negative") -> 1 | E7: =COUNTIFS(Testcase!$B$5:$B$104,$A7,Testcase!$C$5:$C$104,"Edge") -> 5 | F7: =COUNTIFS(Testcase!$B$5:$B$104,$A7,Testcase!$D$5:$D$104,"P1") -> 6 | G7: =COUNTIFS(Testcase!$B$5:$B$104,$A7,Testcase!$I$5:$I$104,"Pass") -> 0 | H7: =COUNTIFS(Testcase!$B$5:$B$104,$A7,Testcase!$I$5:$I$104,"Fail") -> 0 | I7: =COUNTIFS(Testcase!$B$5:$B$104,$A7,Testcase!$I$5:$I$104,"Blocked") -> 0 | J7: =COUNTIFS(Testcase!$B$5:$B$104,$A7,Testcase!$I$5:$I$104,"N/A") -> 0 | K7: =COUNTIFS(Testcase!$B$5:$B$104,$A7,Testcase!$I$5:$I$104,"Chưa test") -> 8 | L7: =IF(B7=0,0,(B7-K7)/B7) -> 0
A8: 5. Gửi Gopany | B8: =COUNTIF(Testcase!$B$5:$B$104,$A8) -> 18 | C8: =COUNTIFS(Testcase!$B$5:$B$104,$A8,Testcase!$C$5:$C$104,"Positive") -> 4 | D8: =COUNTIFS(Testcase!$B$5:$B$104,$A8,Testcase!$C$5:$C$104,"Negative") -> 3 | E8: =COUNTIFS(Testcase!$B$5:$B$104,$A8,Testcase!$C$5:$C$104,"Edge") -> 11 | F8: =COUNTIFS(Testcase!$B$5:$B$104,$A8,Testcase!$D$5:$D$104,"P1") -> 12 | G8: =COUNTIFS(Testcase!$B$5:$B$104,$A8,Testcase!$I$5:$I$104,"Pass") -> 0 | H8: =COUNTIFS(Testcase!$B$5:$B$104,$A8,Testcase!$I$5:$I$104,"Fail") -> 0 | I8: =COUNTIFS(Testcase!$B$5:$B$104,$A8,Testcase!$I$5:$I$104,"Blocked") -> 0 | J8: =COUNTIFS(Testcase!$B$5:$B$104,$A8,Testcase!$I$5:$I$104,"N/A") -> 0 | K8: =COUNTIFS(Testcase!$B$5:$B$104,$A8,Testcase!$I$5:$I$104,"Chưa test") -> 18 | L8: =IF(B8=0,0,(B8-K8)/B8) -> 0
A9: 6. Kết quả trên Gopany | B9: =COUNTIF(Testcase!$B$5:$B$104,$A9) -> 6 | C9: =COUNTIFS(Testcase!$B$5:$B$104,$A9,Testcase!$C$5:$C$104,"Positive") -> 3 | D9: =COUNTIFS(Testcase!$B$5:$B$104,$A9,Testcase!$C$5:$C$104,"Negative") -> 1 | E9: =COUNTIFS(Testcase!$B$5:$B$104,$A9,Testcase!$C$5:$C$104,"Edge") -> 2 | F9: =COUNTIFS(Testcase!$B$5:$B$104,$A9,Testcase!$D$5:$D$104,"P1") -> 3 | G9: =COUNTIFS(Testcase!$B$5:$B$104,$A9,Testcase!$I$5:$I$104,"Pass") -> 0 | H9: =COUNTIFS(Testcase!$B$5:$B$104,$A9,Testcase!$I$5:$I$104,"Fail") -> 0 | I9: =COUNTIFS(Testcase!$B$5:$B$104,$A9,Testcase!$I$5:$I$104,"Blocked") -> 0 | J9: =COUNTIFS(Testcase!$B$5:$B$104,$A9,Testcase!$I$5:$I$104,"N/A") -> 0 | K9: =COUNTIFS(Testcase!$B$5:$B$104,$A9,Testcase!$I$5:$I$104,"Chưa test") -> 6 | L9: =IF(B9=0,0,(B9-K9)/B9) -> 0
A10: 7. Đồng thời / quyền / hệ thống | B10: =COUNTIF(Testcase!$B$5:$B$104,$A10) -> 8 | C10: =COUNTIFS(Testcase!$B$5:$B$104,$A10,Testcase!$C$5:$C$104,"Positive") -> 2 | D10: =COUNTIFS(Testcase!$B$5:$B$104,$A10,Testcase!$C$5:$C$104,"Negative") -> 0 | E10: =COUNTIFS(Testcase!$B$5:$B$104,$A10,Testcase!$C$5:$C$104,"Edge") -> 6 | F10: =COUNTIFS(Testcase!$B$5:$B$104,$A10,Testcase!$D$5:$D$104,"P1") -> 3 | G10: =COUNTIFS(Testcase!$B$5:$B$104,$A10,Testcase!$I$5:$I$104,"Pass") -> 0 | H10: =COUNTIFS(Testcase!$B$5:$B$104,$A10,Testcase!$I$5:$I$104,"Fail") -> 0 | I10: =COUNTIFS(Testcase!$B$5:$B$104,$A10,Testcase!$I$5:$I$104,"Blocked") -> 0 | J10: =COUNTIFS(Testcase!$B$5:$B$104,$A10,Testcase!$I$5:$I$104,"N/A") -> 0 | K10: =COUNTIFS(Testcase!$B$5:$B$104,$A10,Testcase!$I$5:$I$104,"Chưa test") -> 8 | L10: =IF(B10=0,0,(B10-K10)/B10) -> 0
A11: Tổng cộng | B11: =SUM(B4:B10) -> 100 | C11: =SUM(C4:C10) -> 30 | D11: =SUM(D4:D10) -> 15 | E11: =SUM(E4:E10) -> 55 | F11: =SUM(F4:F10) -> 54 | G11: =SUM(G4:G10) -> 0 | H11: =SUM(H4:H10) -> 0 | I11: =SUM(I4:I10) -> 0 | ... K11: =SUM(K4:K10) -> 100 | L11: =IF(B11=0,0,(B11-K11)/B11) -> 0
A13: Tỉ lệ Pass trên số đã chạy (không tính N/A): | G13: =IF((G11+H11+I11)=0,0,G11/(G11+H11+I11)) -> 0

Sheet Testcase
A1: Testcase – Luồng đồng bộ lịch sử Zalo: Gopany → zaloHub → Gopany
A2: Nguồn: tài liệu luong-dong-bo-gopany.html (cập nhật 26/09/2026). Cột nền vàng (Kết quả, Người test, Ngày test, Ghi chú / Bug) là cột cần điền; Kết quả chọn từ danh sách.
A4: ID | B4: Nhóm | C4: Loại | D4: Ưu tiên | E4: Tiêu đề | F4: Precondition | G4: Steps | H4: Expected Result | I4: Kết quả | J4: Người test | K4: Ngày test | L4: Ghi chú / Bug
A5: QR-01 | B5: 1. Liên kết QR (Gopany) | C5: Positive | D5: P1 | E5: Liên kết lần đầu tài khoản mới (2 mã QR) | F5: Công ty Gopany A. Zalo X chưa từng liên kết. | G5: 1. Liên kết tài khoản → Thêm liên kết 2. Quét mã QR bằng Zalo X 3. Để camera quét tiếp mã thứ 2 4. Xác nhận đăng nhập trên điện thoại | H5: Hộp “Kết nối Zalo” hiện QR loại Zalo PC + đếm ngược. Mã thứ 2 hiện đúng vị trí, cùng cỡ mã cũ. Báo “Kết nối thành công!”, thẻ tài khoản “Đang hoạt động”. zaloHub lưu phiên Zalo PC + công ty A. | I5: Chưa test
A6: QR-02 | B6: 1. Liên kết QR (Gopany) | C6: Positive | D6: P1 | E6: Kết nối lại tài khoản cũ (chỉ 1 mã) | F6: Zalo X đã từng liên kết, đang ở trạng thái ngắt. | G6: 1. Bấm Kết nối trên thẻ X 2. Quét bằng Zalo X 3. Xác nhận trên điện thoại | H6: Chỉ có 1 mã, không hiện mã thứ 2. Kết nối thành công, thẻ “Đang hoạt động”. | I6: Chưa test
A7: QR-03 | B7: 1. Liên kết QR (Gopany) | C7: Edge | D7: P1 | E7: Mã thứ 2 hết hạn (~12s) khi camera không tự quét | F7: Zalo X chưa từng liên kết. | G7: 1. Thêm liên kết → quét mã 1 2. Rời camera khỏi màn hình, chờ >12s 3. Quan sát hộp QR | H7: Có thông báo rõ ràng (hết hạn / làm mới), có cách lấy lại mã; không treo ở trạng thái chờ, không tạo tài khoản dở dang trên zaloHub. (Hành vi chính xác cần PO xác nhận – xem Q1) | I7: Chưa test
A8: QR-04 | B8: 1. Liên kết QR (Gopany) | C8: Edge | D8: P2 | E8: Quét mã thứ 2 sát thời điểm hết hạn (giây 11–12) | F8: Zalo X chưa từng liên kết. | G8: 1. Quét mã 1 2. Cố ý quét mã 2 ở giây ~11 | H8: Hoặc thành công trọn vẹn, hoặc báo lỗi rõ ràng. Không xảy ra trạng thái điện thoại báo OK mà Gopany vẫn chờ. | I8: Chưa test
A9: QR-05 | B9: 1. Liên kết QR (Gopany) | C9: Negative | D9: P1 | E9: Mã “Kết nối” của tài khoản A quét bằng Zalo B | F9: Thẻ tài khoản A đang ngắt. Có Zalo B khác. | G9: 1. Bấm Kết nối trên thẻ A 2. Quét bằng Zalo B | H9: Báo “Lỗi trong quá trình quét QR.” Tài khoản A giữ nguyên (tên, UID, dữ liệu). Zalo B không được thêm. | I9: Chưa test
A10: QR-06 | B10: 1. Liên kết QR (Gopany) | C10: Negative | D10: P1 | E10: Mã QR hết hạn → Làm mới mã | G10: 1. Thêm liên kết 2. Chờ đếm ngược về 0 3. Quét mã cũ 4. Bấm Làm mới mã, quét mã mới | H10: Hết hạn: hiện “Mã QR đã hết hạn”, quét mã cũ không thành công. Mã mới quét được, kết nối thành công. | I10: Chưa test
A11: QR-07 | B11: 1. Liên kết QR (Gopany) | C11: Edge | D11: P2 | E11: Bấm Làm mới mã nhiều lần liên tiếp, quét mã cũ hơn | G11: 1. Thêm liên kết 2. Làm mới mã 3 lần nhanh 3. Quét mã của lần 1 (chụp màn hình trước đó) | H11: Chỉ mã mới nhất hợp lệ; mã cũ bị từ chối. Không tạo nhiều phiên song song. | I11: Chưa test
A12: QR-08 | B12: 1. Liên kết QR (Gopany) | C12: Edge | D12: P1 | E12: Đóng hộp QR giữa lúc đã quét, chưa xác nhận | G12: 1. Quét mã 2. Đóng hộp “Kết nối Zalo” 3. Xác nhận đăng nhập trên điện thoại | H12: Hành vi nhất quán: hoặc không tạo liên kết, hoặc tạo và hiện trên danh sách sau khi tải lại. Không có tài khoản “ma” trên zaloHub mà Gopany không thấy. | I12: Chưa test
A13: QR-09 | B13: 1. Liên kết QR (Gopany) | C13: Edge | D13: P1 | E13: Đang mở Zalo PC trên Windows khi liên kết | F13: Zalo X đang đăng nhập app Zalo PC trên máy tính Windows. | G13: 1. Liên kết X trên Gopany 2. Quan sát app Zalo PC trên máy tính | H13: App Zalo PC trên máy tính bị đăng xuất. Gopany kết nối thành công. | I13: Chưa test
A14: QR-10 | B14: 1. Liên kết QR (Gopany) | C14: Edge | D14: P1 | E14: Zalo PC trên Windows đăng nhập lại SAU khi liên kết | F14: X đã liên kết Gopany (phiên Zalo PC). | G14: 1. Đăng nhập lại app Zalo PC trên máy tính bằng X 2. Kiểm tra Gopany và admin zaloHub | H14: Phiên của zaloHub bị đá: Gopany báo mất kết nối; admin hiện “Mất kết nối”, nút Đồng bộ khoá với lý do tương ứng. (Xem Q2) | I14: Chưa test
A15: QR-11 | B15: 1. Liên kết QR (Gopany) | C15: Positive | D15: P2 | E15: Phiên Zalo Web ở hệ thống khác (Salework) không bị đăng xuất | F15: X đang đăng nhập Zalo Web trên Salework. | G15: 1. Liên kết X trên Gopany 2. Theo dõi Salework trong lúc quét | H15: Salework chỉ mất kết nối ~2 giây rồi tự nối lại, vẫn đăng nhập. | I15: Chưa test
A16: QR-12 | B16: 1. Liên kết QR (Gopany) | C16: Positive | D16: P3 | E16: Thông báo “Đang đồng bộ lịch sử” phía Gopany khi liên kết lại | F16: X từng liên kết Gopany, có hội thoại cũ trên Gopany. | G16: 1. Kết nối lại X 2. Quan sát hộp QR sau khi thành công 3. Kiểm tra admin zaloHub | H16: Gopany hiện “Đang đồng bộ lịch sử” vài giây. Admin zaloHub KHÔNG phát sinh lượt Đồng bộ nào. | I16: Chưa test
A17: QR-13 | B17: 1. Liên kết QR (Gopany) | C17: Edge | D17: P1 | E17: Cùng 1 Zalo được 2 công ty Gopany khác nhau liên kết | F17: X đang liên kết ở công ty A. | G17: 1. Công ty B → Thêm liên kết → quét bằng X 2. Kiểm tra A, B và cột Công ty Gopany trên admin | H17: Hành vi theo thiết kế (chặn hoặc chuyển). Admin zaloHub hiển thị đúng công ty đang giữ liên kết. Không lẫn dữ liệu giữa A và B. (Xem Q3) | I17: Chưa test
A18: QR-14 | B18: 1. Liên kết QR (Gopany) | C18: Edge | D18: P2 | E18: 2 người cùng công ty mở QR cho 2 Zalo khác nhau cùng lúc | G18: 1. Tab 1: Thêm liên kết, quét bằng Zalo X 2. Tab 2: Thêm liên kết, quét bằng Zalo Y (gần như đồng thời) | H18: Cả 2 thành công, đúng tên/UID, không tráo mã giữa 2 tab. | I18: Chưa test
A19: QR-15 | B19: 1. Liên kết QR (Gopany) | C19: Edge | D19: P2 | E19: Mất mạng trên máy tính khi đang hiện QR | G19: 1. Thêm liên kết 2. Ngắt mạng máy tính 10s rồi bật lại 3. Quét mã | H19: Có thông báo lỗi/tự làm mới mã hợp lý; không treo đếm ngược. | I19: Chưa test
A20: QR-16 | B20: 1. Liên kết QR (Gopany) | C20: Negative | D20: P2 | E20: Từ chối đăng nhập trên điện thoại | G20: 1. Quét mã 2. Bấm từ chối/huỷ trên điện thoại | H20: Gopany không báo thành công, có thông báo phù hợp; không tạo tài khoản. | I20: Chưa test
A21: LS-01 | B21: 2. Danh sách admin zaloHub | C21: Positive | D21: P1 | E21: Tài khoản vừa liên kết hiển thị đúng trạng thái ban đầu | F21: Vừa làm QR-01 xong. | G21: 1. Admin zaloHub → Đồng bộ Gopany 2. Tìm tài khoản X | H21: Phiên “Zalo PC”, Đồng bộ “Chưa đồng bộ”, Gửi Gopany “Chưa gửi”, cột Công ty Gopany = A. Có nút Đồng bộ và Gửi Gopany… | I21: Chưa test
A22: LS-02 | B22: 2. Danh sách admin zaloHub | C22: Positive | D22: P1 | E22: Bấm thẻ số liệu để lọc / bấm lại để bỏ lọc | F22: Có dữ liệu ở cả 4 trạng thái. | G22: 1. Bấm lần lượt 4 thẻ: Đang chạy, Lỗi/chưa trọn, Chưa đồng bộ, Cần quét QR Zalo PC 2. Bấm lại thẻ đang chọn | H22: Mỗi thẻ lọc đúng tập tài khoản; bấm lại bỏ lọc. Thẻ đang chọn có trạng thái nổi bật. | I22: Chưa test
A23: LS-03 | B23: 2. Danh sách admin zaloHub | C23: Positive | D23: P2 | E23: Số trên thẻ đếm theo bộ lọc đang chọn | G23: 1. Chọn Công ty Gopany = A 2. So số trên 4 thẻ với số dòng thực tế khi lọc từng thẻ | H23: Số trên thẻ khớp số dòng khi kết hợp bộ lọc hiện tại + thẻ. | I23: Chưa test
A24: LS-04 | B24: 2. Danh sách admin zaloHub | C24: Edge | D24: P2 | E24: Thẻ và bộ lọc trạng thái chồng nhau / mâu thuẫn | G24: 1. Chọn bộ lọc trạng thái = Thành công 2. Bấm thẻ “Chưa đồng bộ” | H24: Kết quả nhất quán (rỗng hoặc thẻ ghi đè bộ lọc) và có trạng thái rỗng rõ ràng, không lỗi. | I24: Chưa test
A25: LS-05 | B25: 2. Danh sách admin zaloHub | C25: Positive | D25: P2 | E25: Tìm theo tên / SĐT / UID | G25: 1. Tìm theo tên đầy đủ, 1 phần tên 2. Tìm theo SĐT (có/không số 0 đầu, +84) 3. Tìm theo UID | H25: Trả đúng tài khoản. Ghi nhận hành vi với định dạng SĐT +84 / 84 / 0. | I25: Chưa test
A26: LS-06 | B26: 2. Danh sách admin zaloHub | C26: Positive | D26: P2 | E26: Ô chọn công ty tìm không dấu | F26: Có công ty “Công ty Đồng Hưng”. | G26: 1. Gõ “dong hung” 2. Gõ “ĐỒNG HƯNG”, “Dong Hưng” | H26: Đều ra đúng công ty (không phân biệt dấu, hoa thường, chữ đ/Đ). | I26: Chưa test
A27: LS-07 | B27: 2. Danh sách admin zaloHub | C27: Edge | D27: P2 | E27: Ký tự đặc biệt / chuỗi rất dài trong ô tìm | G27: 1. Nhập %, _, ', ", <script>, emoji 2. Nhập chuỗi 500 ký tự | H27: Không lỗi server, không XSS, trả rỗng hoặc đúng kết quả. | I27: Chưa test
A28: LS-08 | B28: 2. Danh sách admin zaloHub | C28: Positive | D28: P2 | E28: Bộ lọc và số trang lưu trên URL | F28: Có >1 trang dữ liệu. | G28: 1. Chọn bộ lọc + sang trang 2 2. F5 3. Copy URL mở tab khác 4. Bấm Back trình duyệt | H28: Giữ nguyên bộ lọc, trang. Back quay về trạng thái lọc trước. | I28: Chưa test
A29: LS-09 | B29: 2. Danh sách admin zaloHub | C29: Edge | D29: P3 | E29: URL có tham số sai / trang vượt quá | G29: 1. Sửa URL page=9999 2. Sửa giá trị lọc không tồn tại (session=abc) | H29: Không trắng trang; về trang hợp lệ hoặc hiện rỗng + bỏ qua tham số sai. | I29: Chưa test
A30: LS-10 | B30: 2. Danh sách admin zaloHub | C30: Edge | D30: P2 | E30: Đang ở trang cuối thì lọc làm giảm số trang | G30: 1. Sang trang 3 2. Áp bộ lọc chỉ còn 1 trang | H30: Tự về trang 1, không hiển thị rỗng giả. | I30: Chưa test
A31: LS-11 | B31: 2. Danh sách admin zaloHub | C31: Positive | D31: P2 | E31: Bảng tự làm mới ~5s khi có lượt đang chạy | F31: Có 1 lượt đồng bộ đang chạy. | G31: 1. Mở bảng, quan sát cột Đồng bộ 2. Khi lượt xong, quan sát tiếp | H31: Cột cập nhật ~5s/lần; hết lượt chạy thì ngừng tự làm mới. Không mất bộ lọc / vị trí cuộn khi làm mới. | I31: Chưa test
A32: LS-12 | B32: 2. Danh sách admin zaloHub | C32: Positive | D32: P2 | E32: Hộp thoại lịch sử hiển thị đủ thông tin | G32: 1. Bấm Gửi Gopany… trên 1 dòng | H32: Đầu hộp: phiên, công ty Gopany, thời điểm liên kết. Có khung 1, khung 2, mục “Các lượt gần đây” (thu gọn sẵn, tối đa 10 lượt). | I32: Chưa test
A33: LS-13 | B33: 2. Danh sách admin zaloHub | C33: Edge | D33: P3 | E33: Tài khoản có >10 lượt | F33: Tài khoản đã chạy 12 lượt. | G33: 1. Mở hộp thoại → mở “Các lượt gần đây” | H33: Chỉ hiện 10 lượt mới nhất, đúng thứ tự thời gian giảm dần. | I33: Chưa test
A34: LS-14 | B34: 2. Danh sách admin zaloHub | C34: Positive | D34: P2 | E34: Dòng tài khoản mất kết nối | F34: Tài khoản X bị mất kết nối. | G34: 1. Tìm X trên bảng | H34: Cột Tài khoản có nhãn “Mất kết nối”, nút Đồng bộ khoá. | I34: Chưa test
A35: LS-15 | B35: 2. Danh sách admin zaloHub | C35: Edge | D35: P3 | E35: Tên tài khoản rất dài / có emoji / không có SĐT | G35: 1. Xem dòng và hộp thoại của tài khoản đó trên desktop và màn hình hẹp | H35: Không vỡ layout, hiển thị cắt gọn hợp lý. | I35: Chưa test
A36: SY-01 | B36: 3. Đồng bộ | C36: Positive | D36: P1 | E36: Đồng bộ thành công tài khoản Zalo PC | F36: X phiên Zalo PC, đang kết nối, chưa đồng bộ. Điện thoại mở Zalo, màn hình sáng. | G36: 1. Bấm Đồng bộ 2. Đọc hộp xác nhận 3. Bấm Đồng bộ trong hộp 4. Theo dõi tiến độ đến khi xong | H36: Hộp “Đồng bộ lịch sử tin nhắn?” có tên X. Toast “Đã bắt đầu đồng bộ”. Tiến độ qua đủ 5 bước + % + “N hội thoại · M tin”. Kết thúc: khung 1 “Đã đồng bộ” + giờ; nhật ký “Đồng bộ — Thành công”, nguồn “Trang admin” + tên admin. | I36: Chưa test
A37: SY-02 | B37: 3. Đồng bộ | C37: Negative | D37: P2 | E37: Bấm Huỷ ở hộp xác nhận | G37: 1. Bấm Đồng bộ → Huỷ | H37: Không phát sinh lượt, không đổi trạng thái. | I37: Chưa test
A38: SY-03 | B38: 3. Đồng bộ | C38: Negative | D38: P1 | E38: Nút khoá: phiên Zalo Web | F38: Tài khoản phiên Zalo Web. | G38: 1. Rê chuột nút Đồng bộ | H38: Nút khoá, tooltip “Cần phiên Zalo PC — khách quét lại mã QR Zalo PC”. Tài khoản nằm ở thẻ “Cần quét QR Zalo PC”. | I38: Chưa test
A39: SY-04 | B39: 3. Đồng bộ | C39: Negative | D39: P1 | E39: Nút khoá: mất kết nối | F39: Tài khoản phiên Zalo PC nhưng mất kết nối. | G39: 1. Rê chuột nút Đồng bộ | H39: Tooltip “Tài khoản mất kết nối — khách cần kết nối lại”. | I39: Chưa test
A40: SY-05 | B40: 3. Đồng bộ | C40: Negative | D40: P1 | E40: Nút khoá: không có quyền | F40: Admin không có quyền quản lý tài khoản Zalo. | G40: 1. Rê chuột Đồng bộ và Gửi Gopany | H40: Cả 2 khoá, tooltip “Không có quyền”. | I40: Chưa test
A41: SY-06 | B41: 3. Đồng bộ | C41: Negative | D41: P1 | E41: Nút khoá: đang gửi Gopany | F41: Tài khoản đang có lượt Gửi Gopany chạy. | G41: 1. Rê chuột Đồng bộ | H41: Tooltip “Đang gửi sang Gopany — đợi gửi xong”. | I41: Chưa test
...

Sheet Cần làm rõ với PO
A1: Điểm tài liệu chưa nói rõ – cần PO/Dev chốt trước khi test
A3: # | B3: Câu hỏi | C3: Testcase liên quan | D3: Trả lời
A4: Q1 | B4: Mã QR thứ 2 hết hạn (~12s) thì UI xử lý thế nào: tự làm mới, quay về mã 1, hay báo lỗi? | C4: QR-03, QR-04
A5: Q2 | B5: Khi khách đăng nhập lại Zalo PC trên máy tính, zaloHub có tự báo mất kết nối ngay không, Gopany hiển thị gì? | C5: QR-10, SY-18
A6: Q3 | B6: Một Zalo liên kết ở công ty A, sau đó công ty B liên kết cùng Zalo: chặn hay chuyển? Nếu chuyển, lịch sử đã đồng bộ khi còn ở A có được gửi cho B không? (rủi ro lộ dữ liệu) | C6: QR-13, SD-09
A7: Q4 | B7: Khi nhiều điều kiện khoá cùng lúc, tooltip hiển thị lý do nào trước? | C7: SY-07
A8: Q5 | B8: Có timeout cho lượt Đồng bộ (điện thoại khoá màn hình) và lượt Gửi (Gopany không phản hồi) không? Bao lâu? | C8: SY-10, SY-11, SD-13
A9: Q6 | B9: Đồng bộ lại: tin đã xoá / thu hồi / sửa trên điện thoại xử lý thế nào ở zaloHub và Gopany (vì Gopany chỉ bỏ tin đã có)? | C9: SY-25
A10: Q7 | B10: Lượt đồng bộ gần nhất “Đã hủy” hoặc “Bị gián đoạn” (dữ liệu có thể thiếu) có chặn Gửi Gopany không? Tài liệu chỉ nêu “bị lỗi”. | C10: CN-06, SD-07
A11: Q8 | B11: Tài khoản chưa từng đồng bộ có được bấm Gửi Gopany không? Nếu được, kết quả là gì? | C11: SD-06
A12: Q9 | B12: Các tài khoản cùng 1 công ty Gopany có gửi song song được không? (tài liệu chỉ nói “các tài khoản Gopany khác nhau”) | C12: SD-16
A13: Q10 | B13: Tin lịch sử đổ vào Gopany có bị tính là chưa đọc / bắn thông báo cho nhân viên không? | C13: RS-06
A14: Q11 | B14: Trong ~5 phút trước khi lượt bị đánh dấu “Bị gián đoạn”, admin có cách nào giải phóng tài khoản không? | C14: CC-02
A15: Q12 | B15: Tìm theo SĐT: hỗ trợ những định dạng nào (0xxx, 84xxx, +84xxx)? | C15: LS-05
